Workbook

Sheet spplist
A1: modnum | B1: modname | C1: species | D1: query | E1: og_name | F1: sedar_spabb | G1: class | H1: order | I1: family | J1: genus | K1: FBname | L1: M | M1: QB | N1: Lmax | O1: TL | P1: Vul | Q1: AR | R1: NearOff | S1: DemPel | T1: ReefSurv | U1: fish | V1: benthcrust | W1: detritus | X1: plants | Y1: cephalopods | Z1: cnidarians | AA1: otherinverts | AB1: zooplankton | AC1: softbottom | AD1: hardbottom | AE1: veg | AF1: coral | AG1: smp.tr | AH1: smp.bl | AI1: smp.vl | AJ1: nmfs.bll | AK1: fwc.vid | AL1: fwc.ins | AM1: fwc.bfc | AN1: rov | AO1: mrip | AP1: hb | AQ1: com | AR1: modnum_mice | AS1: modname_mice
A2: 4 | B2: =VLOOKUP(A2,'model groups'!$A$3:$C$86,2,FALSE) -> pelagic sharks | C2: Carcharhinus plumbeus | D2: CARCHARHINUS PLUMBEUS | E2: CARCHARHINUS PLUMBEUS | G2: Chondrichthyes | H2: Carcharhiniformes | I2: Carcharhinidae | J2: Carcharhinus | K2: Sandbar shark | L2: 0.1575 | M2: 3.5002132 | N2: 183.40606 | O2: 4.34 | P2: 87.51 | Q2: 3.178275 | R2: nearshore | S2: pelagic | T2: =IF(OR(AK2=1,AN2=1),"reef","no") -> reef | U2: 0.85768577 | V2: 0.084341765 | W2: 0.0055005502 | X2: 0.00033336668 | Y2: 0.046771345 | Z2: 0 | AA2: 0.0039670634 | AB2: 0.00140014 | AC2: 1 | AD2: 0 | AE2: 0 | AF2: 1 | AG2: 0 | AH2: 1 | AI2: 0 | AJ2: 1 | AK2: 0 | AL2: 0 | AM2: 0 | AN2: 1 | AO2: 0 | AP2: 0 | AQ2: 1 | AR2: 1 | AS2: sharks
A3: 4 | B3: =VLOOKUP(A3,'model groups'!$A$3:$C$86,2,FALSE) -> pelagic sharks | C3: Galeocerdo cuvier | D3: GALEOCERDO CUVIER | E3: GALEOCERDO CUVIER | G3: Chondrichthyes | H3: Carcharhiniformes | I3: Carcharhinidae | J3: Galeocerdo | K3: Tiger shark | L3: 0.16071429 | M3: 1.0339962 | N3: 747.04676 | O3: 4.53 | P3: 63.83 | Q3: 1.385944 | R3: nearshore | S3: pelagic | T3: =IF(OR(AK3=1,AN3=1),"reef","no") -> no | U3: 0.87132141 | V3: 0.070398152 | W3: 0.024235429 | X3: 0 | Y3: 0.027697635 | Z3: 0 | AA3: 0.0063473747 | AB3: 0 | AC3: 0 | AD3: 0 | AE3: 0 | AF3: 1 | AG3: 0 | AH3: 1 | AI3: 0 | AJ3: 0 | AK3: 0 | AL3: 0 | AM3: 0 | AN3: 0 | AO3: 0 | AP3: 0 | AQ3: 1 | AR3: 1 | AS3: sharks
A4: 4 | B4: =VLOOKUP(A4,'model groups'!$A$3:$C$86,2,FALSE) -> pelagic sharks | C4: Galeocerdo cuvier | D4: GALEOCERDO CUVIERI | E4: GALEOCERDO CUVIERI | G4: Chondrichthyes | H4: Carcharhiniformes | I4: Carcharhinidae | J4: Galeocerdo | K4: Tiger shark | L4: 0.16071429 | M4: 1.0339962 | N4: 747.04676 | O4: 4.53 | P4: 63.83 | Q4: 1.385944 | R4: nearshore | S4: pelagic | T4: =IF(OR(AK4=1,AN4=1),"reef","no") -> no | U4: 0.87132141 | V4: 0.070398152 | W4: 0.024235429 | X4: 0 | Y4: 0.027697635 | Z4: 0 | AA4: 0.0063473747 | AB4: 0 | AC4: 0 | AD4: 0 | AE4: 0 | AF4: 1 | AG4: 0 | AH4: 0 | AI4: 0 | AJ4: 1 | AK4: 0 | AL4: 0 | AM4: 0 | AN4: 0 | AO4: 0 | AP4: 0 | AQ4: 0 | AR4: 1 | AS4: sharks
A5: 4 | B5: =VLOOKUP(A5,'model groups'!$A$3:$C$86,2,FALSE) -> pelagic sharks | C5: Sphyrna lewini | D5: SPHYRNA LEWINI | E5: SPHYRNA LEWINI | G5: Chondrichthyes | H5: Carcharhiniformes | I5: Sphyrnidae | J5: Sphyrna | K5: Scalloped hammerhead | L5: 0.19644867 | M5: 1.8266731 | N5: 432.11198 | O5: 4.0966667 | P5: 81.26 | Q5: 1.80809 | R5: nearshore | S5: pelagic | T5: =IF(OR(AK5=1,AN5=1),"reef","no") -> no | U5: 0.75723237 | V5: 0.18977469 | W5: 0 | X5: 0.00099986671 | Y5: 0.051659778 | Z5: 0 | AA5: 0.0003332889 | AB5: 0 | AC5: 0 | AD5: 0 | AE5: 0 | AF5: 1 | AG5: 0 | AH5: 1 | AI5: 0 | AJ5: 1 | AK5: 0 | AL5: 0 | AM5: 0 | AN5: 0 | AO5: 0 | AP5: 0 | AQ5: 1 | AR5: 1 | AS5: sharks
A6: 4 | B6: =VLOOKUP(A6,'model groups'!$A$3:$C$86,2,FALSE) -> pelagic sharks | C6: Sphyrna mokarran | D6: SPHYRNA MOKARRAN | E6: SPHYRNA MOKARRAN | G6: Chondrichthyes | H6: Carcharhiniformes | I6: Sphyrnidae | J6: Sphyrna | K6: Great hammerhead | L6: 0.15 | M6: 1.7045037 | N6: 609.59738 | O6: 4.3266667 | P6: 86.03 | Q6: 1.85353 | R6: nearshore | S6: pelagic | T6: =IF(OR(AK6=1,AN6=1),"reef","no") -> no | U6: 0.853 | V6: 0.112 | W6: 0 | X6: 0.002 | Y6: 0.033 | Z6: 0 | AA6: 0 | AB6: 0 | AC6: 0 | AD6: 0 | AE6: 0 | AF6: 0 | AG6: 0 | AH6: 1 | AI6: 0 | AJ6: 1 | AK6: 0 | AL6: 0 | AM6: 0 | AN6: 0 | AO6: 0 | AP6: 0 | AQ6: 1 | AR6: 1 | AS6: sharks
A7: 4 | B7: =VLOOKUP(A7,'model groups'!$A$3:$C$86,2,FALSE) -> pelagic sharks | C7: Mustelus sinusmexicanus | D7: MUSTELUS SINUSMEXICANUS | E7: MUSTELUS SINUSMEXICANUS | G7: Chondrichthyes | H7: Carcharhiniformes | I7: Triakidae | J7: Mustelus | K7: Gulf smoothhound | L7: 0.4859777 | M7: 5.0075481 | N7: 85.617935 | O7: 3.755 | P7: 63.38 | Q7: 1.0128385 | R7: offshore | S7: pelagic | T7: =IF(OR(AK7=1,AN7=1),"reef","no") -> no | U7: 0.10079856 | V7: 0.77477465 | W7: 0.012256968 | X7: 0 | Y7: 0.015142641 | Z7: 0 | AA7: 0.095912915 | AB7: 0.0011142697 | AC7: 1 | AD7: 0 | AE7: 0 | AF7: 0 | AG7: 0 | AH7: 0 | AI7: 0 | AJ7: 1 | AK7: 0 | AL7: 0 | AM7: 0 | AN7: 0 | AO7: 0 | AP7: 0 | AQ7: 0 | AR7: 1 | AS7: sharks
A8: 5 | B8: =VLOOKUP(A8,'model groups'!$A$3:$C$86,2,FALSE) -> large demersal sharks | D8: CHONDRICHTHYES | E8: CHONDRICHTHYES | G8: Chondrichthyes | K8: SHARKS | AG8: 0 | AH8: 0 | AI8: 0 | AJ8: 0 | AK8: 0 | AL8: 0 | AM8: 0 | AN8: 0 | AO8: 0 | AP8: 0 | AQ8: 1 | AR8: 1 | AS8: sharks
A9: 5 | B9: =VLOOKUP(A9,'model groups'!$A$3:$C$86,2,FALSE) -> large demersal sharks | C9: Carcharhinus acronotus | D9: CARCHARHINUS ACRONOTUS | E9: CARCHARHINUS ACRONOTUS | G9: Chondrichthyes | H9: Carcharhiniformes | I9: Carcharhinidae | J9: Carcharhinus | K9: Blacknose shark | L9: 0.73346285 | M9: 3.6548582 | N9: 103.6 | O9: 4.3233333 | P9: 69.76 | Q9: 1.82749 | R9: offshore | S9: reef-associated | T9: =IF(OR(AK9=1,AN9=1),"reef","no") -> no | U9: 0.982 | V9: 0.012000001 | W9: 0 | X9: 0 | Y9: 0 | Z9: 0 | AA9: 0.0060000004 | AB9: 0 | AC9: 0 | AD9: 0 | AE9: 0 | AF9: 0 | AG9: 0 | AH9: 1 | AI9: 0 | AJ9: 1 | AK9: 0 | AL9: 0 | AM9: 1 | AN9: 0 | AO9: 0 | AP9: 0 | AQ9: 1 | AR9: 1 | AS9: sharks
A10: 5 | B10: =VLOOKUP(A10,'model groups'!$A$3:$C$86,2,FALSE) -> large demersal sharks | C10: Carcharhinus brevipinna | D10: CARCHARHINUS BREVIPINNA | E10: CARCHARHINUS BREVIPINNA | G10: Chondrichthyes | H10: Carcharhiniformes | I10: Carcharhinidae | J10: Carcharhinus | K10: Spinner shark | L10: 0.34652701 | M10: 6.319572 | N10: 214 | O10: 4.28 | P10: 62.25 | Q10: 5.87939 | R10: offshore | S10: reef-associated | T10: =IF(OR(AK10=1,AN10=1),"reef","no") -> no | U10: 0.911 | V10: 0.02 | W10: 0 | X10: 0.01 | Y10: 0.059000002 | Z10: 0 | AA10: 0 | AB10: 0 | AC10: 0 | AD10: 0 | AE10: 0 | AF10: 0 | AG10: 0 | AH10: 1 | AI10: 0 | AJ10: 1 | AK10: 0 | AL10: 0 | AM10: 0 | AN10: 0 | AO10: 0 | AP10: 0 | AQ10: 1 | AR10: 1 | AS10: sharks
A11: 5 | B11: =VLOOKUP(A11,'model groups'!$A$3:$C$86,2,FALSE) -> large demersal sharks | C11: Carcharhinus falciformis | D11: CARCHARHINUS FALCIFORMIS | E11: CARCHARHINUS FALCIFORMIS | G11: Chondrichthyes | H11: Carcharhiniformes | I11: Carcharhinidae | J11: Carcharhinus | K11: Silky shark | L11: 0.25935608 | M11: 2.0817524 | N11: 352.87213 | O11: 4.4766667 | P11: 79.03 | Q11: 2.02629 | R11: offshore | S11: reef-associated | T11: =IF(OR(AK11=1,AN11=1),"reef","no") -> no | U11: 0.607 | V11: 0.017 | W11: 0.050999998 | X11: 0 | Y11: 0.3095 | Z11: 0 | AA11: 0.015499999 | AB11: 0 | AC11: 0 | AD11: 0 | AE11: 0 | AF11: 0 | AG11: 0 | AH11: 0 | AI11: 0 | AJ11: 1 | AK11: 0 | AL11: 0 | AM11: 0 | AN11: 0 | AO11: 0 | AP11: 0 | AQ11: 1 | AR11: 1 | AS11: sharks
A12: 5 | B12: =VLOOKUP(A12,'model groups'!$A$3:$C$86,2,FALSE) -> large demersal sharks | C12: Carcharhinus leucas | D12: CARCHARHINUS LEUCAS | E12: CARCHARHINUS LEUCAS | G12: Chondrichthyes | H12: Carcharhiniformes | I12: Carcharhinidae | J12: Carcharhinus | K12: Bull shark | L12: 0.21678143 | M12: 2.3837994 | N12: 362.79166 | O12: 4.2866667 | P12: 87.54 | Q12: 1.44355 | R12: nearshore | S12: reef-associated | T12: =IF(OR(AK12=1,AN12=1),"reef","no") -> no | U12: 0.9231579 | V12: 0.02736842 | W12: 0 | X12: 0.042105263 | Y12: 0.0052631579 | Z12: 0 | AA12: 0.0021052632 | AB12: 0 | AC12: 0 | AD12: 0 | AE12: 0 | AF12: 0 | AG12: 0 | AH12: 1 | AI12: 0 | AJ12: 1 | AK12: 0 | AL12: 0 | AM12: 0 | AN12: 0 | AO12: 0 | AP12: 0 | AQ12: 1 | AR12: 1 | AS12: sharks
A13: 5 | B13: =VLOOKUP(A13,'model groups'!$A$3:$C$86,2,FALSE) -> large demersal sharks | C13: Carcharhinus limbatus | D13: CARCHARHINUS LIMBATUS | E13: CARCHARHINUS LIMBATUS | G13: Chondrichthyes | H13: Carcharhiniformes | I13: Carcharhinidae | J13: Carcharhinus | K13: Blacktip shark | L13: 0.43089197 | M13: 3.5664409 | N13: 176 | O13: 4.3266667 | P13: 55.45 | Q13: 2.000455 | R13: nearshore | S13: reef-associated | T13: =IF(OR(AK13=1,AN13=1),"reef","no") -> reef | U13: 0.95108422 | V13: 0.01260716 | W13: 0 | X13: 0.00050428643 | Y13: 0.034291477 | Z13: 0 | AA13: 0.0015128593 | AB13: 0 | AC13: 0 | AD13: 0 | AE13: 0 | AF13: 0 | AG13: 0 | AH13: 1 | AI13: 0 | AJ13: 1 | AK13: 0 | AL13: 0 | AM13: 0 | AN13: 1 | AO13: 0 | AP13: 0 | AQ13: 1 | AR13: 1 | AS13: sharks
A14: 5 | B14: =VLOOKUP(A14,'model groups'!$A$3:$C$86,2,FALSE) -> large demersal sharks | D14: CARCHARHINUS | E14: CARCHARHINUS | G14: Chondrichthyes | H14: Carcharhiniformes | I14: Carcharhinidae | J14: Carcharhinus | T14: =IF(OR(AK14=1,AN14=1),"reef","no") -> no | AG14: 0 | AH14: 0 | AI14: 0 | AJ14: 0 | AK14: 0 | AL14: 0 | AM14: 0 | AN14: 0 | AO14: 1 | AP14: 0 | AQ14: 0 | AR14: 1 | AS14: sharks
A15: 5 | B15: =VLOOKUP(A15,'model groups'!$A$3:$C$86,2,FALSE) -> large demersal sharks | D15: CARCHARHINUS | E15: CARCHARHINUS SP. | G15: Chondrichthyes | H15: Carcharhiniformes | I15: Carcharhinidae | J15: Carcharhinus | T15: =IF(OR(AK15=1,AN15=1),"reef","no") -> reef | AG15: 0 | AH15: 0 | AI15: 0 | AJ15: 0 | AK15: 0 | AL15: 0 | AM15: 0 | AN15: 1 | AO15: 0 | AP15: 0 | AQ15: 0 | AR15: 1 | AS15: sharks
A16: 5 | B16: =VLOOKUP(A16,'model groups'!$A$3:$C$86,2,FALSE) -> large demersal sharks | D16: NEGAPRION BREVIROSTRIS | E16: NEGAPRION BREVIROSTRIS | G16: Chondrichthyes | H16: Carcharhiniformes | I16: Carcharhinidae | J16: Negaprion | K16: Negaprion brevirostris | AR16: 1 | AS16: sharks
A17: 5 | B17: =VLOOKUP(A17,'model groups'!$A$3:$C$86,2,FALSE) -> large demersal sharks | D17: CARCHARHINIDAE | E17: CARCHARHINIDAE | G17: Chondrichthyes | H17: Carcharhiniformes | I17: Carcharhinidae | T17: =IF(OR(AK17=1,AN17=1),"reef","no") -> no | AG17: 0 | AH17: 0 | AI17: 0 | AJ17: 0 | AK17: 0 | AL17: 0 | AM17: 0 | AN17: 0 | AO17: 1 | AP17: 0 | AQ17: 0 | AR17: 1 | AS17: sharks
A18: 5 | B18: =VLOOKUP(A18,'model groups'!$A$3:$C$86,2,FALSE) -> large demersal sharks | C18: Ginglymostoma cirratum | D18: GINGLYMOSTOMA CIRRATUM | E18: GINGLYMOSTOMA CIRRATUM | G18: Chondrichthyes | H18: Orectolobiformes | I18: Ginglymostomatidae | J18: Ginglymostoma | K18: Nurse shark | L18: 0.14401438 | N18: 432.11198 | O18: 4.0733333 | P18: 81.38 | R18: nearshore | S18: reef-associated | T18: =IF(OR(AK18=1,AN18=1),"reef","no") -> no | U18: 0.38 | V18: 0.18533333 | W18: 0 | X18: 0 | Y18: 0.138 | Z18: 0 | AA18: 0.29666667 | AB18: 0 | AC18: 1 | AD18: 0 | AE18: 0 | AF18: 1 | AG18: 0 | AH18: 1 | AI18: 0 | AJ18: 1 | AK18: 0 | AL18: 0 | AM18: 0 | AN18: 0 | AO18: 0 | AP18: 0 | AQ18: 0 | AR18: 1 | AS18: sharks
A19: 6 | B19: =VLOOKUP(A19,'model groups'!$A$3:$C$86,2,FALSE) -> small sharks and rays | D19: RAJIFORMES | E19: RAJIFORMES | G19: Chondrichthyes | H19: Rajiformes | K19: RAYS | AG19: 0 | AH19: 0 | AI19: 0 | AJ19: 0 | AK19: 0 | AL19: 0 | AM19: 0 | AN19: 0 | AO19: 0 | AP19: 0 | AQ19: 1 | AR19: 0 | AS19: omitted
A20: 6 | B20: =VLOOKUP(A20,'model groups'!$A$3:$C$86,2,FALSE) -> small sharks and rays | C20: Carcharhinus isodon | D20: CARCHARHINUS ISODON | E20: CARCHARHINUS ISODON | G20: Chondrichthyes | H20: Carcharhiniformes | I20: Carcharhinidae | J20: Carcharhinus | K20: Finetooth shark | L20: 0.55900621 | M20: 3.0532243 | N20: 193.42893 | O20: 4.25 | P20: 60.19 | Q20: 2.56489 | R20: offshore | S20: demersal | T20: =IF(OR(AK20=1,AN20=1),"reef","no") -> no | U20: 0.959 | V20: 0 | W20: 0 | X20: 0 | Y20: 0 | Z20: 0 | AA20: 0.040999998 | AB20: 0 | AC20: 0 | AD20: 0 | AE20: 0 | AF20: 0 | AG20: 0 | AH20: 1 | AI20: 0 | AJ20: 0 | AK20: 0 | AL20: 0 | AM20: 0 | AN20: 0 | AO20: 0 | AP20: 0 | AQ20: 1 | AR20: 0 | AS20: omitted
A21: 6 | B21: =VLOOKUP(A21,'model groups'!$A$3:$C$86,2,FALSE) -> small sharks and rays | C21: Rhizoprionodon terraenovae | D21: RHIZOPRIONODON TERRAENOVAE | E21: RHIZOPRIONODON TERRAENOVAE | G21: Chondrichthyes | H21: Carcharhiniformes | I21: Carcharhinidae | J21: Rhizoprionodon | K21: Atlantic sharpnose shark | L21: 0.55921967 | M21: 4.5484854 | N21: 112.96256 | O21: 4.3033333 | P21: 45.96 | Q21: 1.55083 | R21: nearshore | S21: demersal | T21: =IF(OR(AK21=1,AN21=1),"reef","no") -> no | U21: 0.765 | V21: 0.162 | W21: 0.027 | X21: 0 | Y21: 0.017 | Z21: 0 | AA21: 0.029 | AB21: 0 | AC21: 0 | AD21: 0 | AE21: 0 | AF21: 0 | AG21: 0 | AH21: 1 | AI21: 1 | AJ21: 1 | AK21: 0 | AL21: 0 | AM21: 1 | AN21: 0 | AO21: 0 | AP21: 0 | AQ21: 1 | AR21: 0 | AS21: omitted
A22: 6 | B22: =VLOOKUP(A22,'model groups'!$A$3:$C$86,2,FALSE) -> small sharks and rays | D22: BATHYTOSHIA CENTROURA | E22: BATHYTOSHIA CENTROURA | G22: Chondrichthyes | H22: Myliobatiformes | I22: Dasyatidae | J22: Bathytoshia | K22: Bathytoshia centroura | AR22: 0 | AS22: omitted
A23: 6 | B23: =VLOOKUP(A23,'model groups'!$A$3:$C$86,2,FALSE) -> small sharks and rays | C23: Dasyatis americana | D23: DASYATIS AMERICANA | E23: DASYATIS AMERICANA | G23: Chondrichthyes | H23: Myliobatiformes | I23: Dasyatidae | J23: Dasyatis | K23: Southern stingray | L23: 0.16170357 | N23: 203.44341 | O23: 3.57 | P23: 76.83 | R23: nearshore | S23: reef-associated | T23: =IF(OR(AK23=1,AN23=1),"reef","no") -> reef | U23: 0.12719682 | V23: 0.62235944 | W23: 0.049548761 | X23: 0.00099997502 | Y23: 0 | Z23: 0 | AA23: 0.19989501 | AB23: 0 | AC23: 1 | AD23: 0 | AE23: 1 | AF23: 0 | AG23: 0 | AH23: 1 | AI23: 0 | AJ23: 0 | AK23: 0 | AL23: 0 | AM23: 1 | AN23: 1 | AO23: 0 | AP23: 0 | AQ23: 0 | AR23: 0 | AS23: omitted
A24: 6 | B24: =VLOOKUP(A24,'model groups'!$A$3:$C$86,2,FALSE) -> small sharks and rays | C24: Dasyatis centroura | D24: DASYATIS CENTROURA | E24: DASYATIS CENTROURA | G24: Chondrichthyes | H24: Myliobatiformes | I24: Dasyatidae | J24: Dasyatis | K24: Roughtail stingray | L24: 0.1934494 | N24: 303.20407 | O24: 3.7933333 | P24: 80.94 | R24: nearshore | S24: demersal | T24: =IF(OR(AK24=1,AN24=1),"reef","no") -> no | U24: 0.31100001 | V24: 0.68799999 | W24: 0.001 | X24: 0 | Y24: 0 | Z24: 0 | AA24: 0 | AB24: 0 | AC24: 0 | AD24: 0 | AE24: 0 | AF24: 0 | AG24: 0 | AH24: 0 | AI24: 0 | AJ24: 0 | AK24: 0 | AL24: 0 | AM24: 1 | AN24: 0 | AO24: 0 | AP24: 0 | AQ24: 0 | AR24: 0 | AS24: omitted
A25: 6 | B25: =VLOOKUP(A25,'model groups'!$A$3:$C$86,2,FALSE) -> small sharks and rays | C25: Dasyatis sabina | D25: DASYATIS SABINA | E25: DASYATIS SABINA | G25: Chondrichthyes | H25: Myliobatiformes | I25: Dasyatidae | J25: Dasyatis | K25: Atlantic stingray | L25: 0.48826282 | N25: 126.5 | O25: 3.45 | P25: 76.13 | R25: nearshore | S25: demersal | T25: =IF(OR(AK25=1,AN25=1),"reef","no") -> reef | U25: 0.081079503 | V25: 0.44016136 | W25: 0.2496562 | X25: 0.00033338612 | Y25: 0.0029004592 | Z25: 0 | AA25: 0.22273527 | AB25: 0.0031338295 | AC25: 0 | AD25: 0 | AE25: 0 | AF25: 0 | AG25: 0 | AH25: 1 | AI25: 0 | AJ25: 0 | AK25: 0 | AL25: 1 | AM25: 0 | AN25: 1 | AO25: 0 | AP25: 0 | AQ25: 0 | AR25: 0 | AS25: omitted
A26: 6 | B26: =VLOOKUP(A26,'model groups'!$A$3:$C$86,2,FALSE) -> small sharks and rays | D26: HYPANUS SAY | E26: HYPANUS SAY | G26: Chondrichthyes | H26: Myliobatiformes | I26: Dasyatidae | J26: Dasyatis | K26: Dasyatis say | AR26: 0 | AS26: omitted
A27: 6 | B27: =VLOOKUP(A27,'model groups'!$A$3:$C$86,2,FALSE) -> small sharks and rays | C27: Dasyatis say | D27: DASYATIS SAY | E27: DASYATIS SAY | G27: Chondrichthyes | H27: Myliobatiformes | I27: Dasyatidae | J27: Dasyatis | AR27: 0 | AS27: omitted
A28: 6 | B28: =VLOOKUP(A28,'model groups'!$A$3:$C$86,2,FALSE) -> small sharks and rays | D28: HYPANUS AMERICANUS | E28: HYPANUS AMERICANUS | G28: Chondrichthyes | H28: Myliobatiformes | I28: Dasyatidae | J28: Hypanus | K28: Hypanus americanus | AR28: 0 | AS28: omitted
A29: 6 | B29: =VLOOKUP(A29,'model groups'!$A$3:$C$86,2,FALSE) -> small sharks and rays | D29: HYPANUS SABINUS | E29: HYPANUS SABINUS | G29: Chondrichthyes | H29: Myliobatiformes | I29: Dasyatidae | J29: Hypanus | K29: Hypanus sabinus | AR29: 0 | AS29: omitted
A30: 6 | B30: =VLOOKUP(A30,'model groups'!$A$3:$C$86,2,FALSE) -> small sharks and rays | C30: Gymnura micrura | D30: GYMNURA MICRURA | E30: GYMNURA MICRURA | G30: Chondrichthyes | H30: Myliobatiformes | I30: Gymnuridae | J30: Gymnura | K30: Smooth butterfly ray | L30: 0.35368684 | N30: 140.19958 | O30: 3.56 | P30: 49.54 | R30: nearshore | S30: demersal | T30: =IF(OR(AK30=1,AN30=1),"reef","no") -> no | U30: 0.069000002 | V30: 0 | W30: 0.931 | X30: 0 | Y30: 0 | Z30: 0 | AA30: 0 | AB30: 0 | AC30: 1 | AD30: 0 | AE30: 0 | AF30: 0 | AG30: 0 | AH30: 0 | AI30: 0 | AJ30: 0 | AK30: 0 | AL30: 0 | AM30: 1 | AN30: 0 | AO30: 0 | AP30: 0 | AQ30: 0 | AR30: 0 | AS30: omitted
A31: 6 | B31: =VLOOKUP(A31,'model groups'!$A$3:$C$86,2,FALSE) -> small sharks and rays | D31: GYMNURA LESSAE | E31: GYMNURA LESSAE | G31: Chondrichthyes | H31: Myliobatiformes | I31: Gymnuridae | J31: Gymnura | K31: Gymnura lessae | AR31: 0 | AS31: omitted
A32: 6 | B32: =VLOOKUP(A32,'model groups'!$A$3:$C$86,2,FALSE) -> small sharks and rays | C32: Aetobatus narinari | D32: AETOBATUS NARINARI | E32: AETOBATUS NARINARI | G32: Chondrichthyes | H32: Myliobatiformes | I32: Myliobatidae | J32: Aetobatus | AR32: 0 | AS32: omitted
A33: 6 | B33: =VLOOKUP(A33,'model groups'!$A$3:$C$86,2,FALSE) -> small sharks and rays | C33: Myliobatis freminvillii | D33: MYLIOBATIS FREMINVILLII | E33: MYLIOBATIS FREMINVILLII | G33: Chondrichthyes | H33: Myliobatiformes | I33: Myliobatidae | J33: Myliobatis | T33: =IF(OR(AK33=1,AN33=1),"reef","no") -> no | AG33: 0 | AH33: 1 | AI33: 0 | AJ33: 0 | AK33: 0 | AL33: 0 | AM33: 0 | AN33: 0 | AO33: 0 | AP33: 0 | AQ33: 0 | AR33: 0 | AS33: omitted
A34: 6 | B34: =VLOOKUP(A34,'model groups'!$A$3:$C$86,2,FALSE) -> small sharks and rays | C34: Myliobatis freminvillei | D34: MYLIOBATIS FREMINVILLEI | E34: MYLIOBATIS FREMINVILLEI | G34: Chondrichthyes | H34: Myliobatiformes | I34: Myliobatidae | J34: Myliobatis | AR34: 0 | AS34: omitted
A35: 6 | B35: =VLOOKUP(A35,'model groups'!$A$3:$C$86,2,FALSE) -> small sharks and rays | D35: RHINOPTERA BONASUS | E35: RHINOPTERA BONASUS | G35: Chondrichthyes | H35: Myliobatiformes | I35: Myliobatidae | J35: Rhinoptera | K35: Rhinoptera bonasus | AR35: 0 | AS35: omitted
A36: 6 | B36: =VLOOKUP(A36,'model groups'!$A$3:$C$86,2,FALSE) -> small sharks and rays | C36: Raja eglanteria | D36: RAJA EGLANTERIA | E36: RAJA EGLANTERIA | G36: Chondrichthyes | H36: Rajiformes | I36: Rajidae | J36: Raja | K36: Clearnose skate | L36: 0.48230137 | N36: 86.632978 | O36: 3.7133333 | P36: 50.9 | R36: nearshore | S36: demersal | T36: =IF(OR(AK36=1,AN36=1),"reef","no") -> no | U36: 0.23757143 | V36: 0.55242857 | W36: 0.15542857 | X36: 0 | Y36: 0 | Z36: 0 | AA36: 0.024857143 | AB36: 0.029714287 | AC36: 0 | AD36: 0 | AE36: 0 | AF36: 0 | AG36: 1 | AH36: 0 | AI36: 0 | AJ36: 0 | AK36: 0 | AL36: 0 | AM36: 1 | AN36: 0 | AO36: 0 | AP36: 0 | AQ36: 0 | AR36: 0 | AS36: omitted
A37: 6 | B37: =VLOOKUP(A37,'model groups'!$A$3:$C$86,2,FALSE) -> small sharks and rays | C37: Raja texana | D37: RAJA TEXANA | E37: RAJA TEXANA | G37: Chondrichthyes | H37: Rajiformes | I37: Rajidae | J37: Raja | K37: Roundel skate | L37: 0.64585018 | N37: 55.063002 | O37: 3.84 | P37: 46.56 | R37: offshore | S37: demersal | T37: =IF(OR(AK37=1,AN37=1),"reef","no") -> no | U37: 0.23757143 | V37: 0.55242857 | W37: 0.15542857 | X37: 0 | Y37: 0 | Z37: 0 | AA37: 0.024857143 | AB37: 0.029714287 | AC37: 0 | AD37: 0 | AE37: 0 | AF37: 0 | AG37: 1 | AH37: 0 | AI37: 0 | AJ37: 0 | AK37: 0 | AL37: 0 | AM37: 1 | AN37: 0 | AO37: 0 | AP37: 0 | AQ37: 0 | AR37: 0 | AS37: omitted
A38: 6 | B38: =VLOOKUP(A38,'model groups'!$A$3:$C$86,2,FALSE) -> small sharks and rays | D38: ROSTRORAJA EGLANTERIA | E38: ROSTRORAJA EGLANTERIA | G38: Chondrichthyes | H38: Rajiformes | I38: Rajidae | J38: Rostroraja | K38: Rostroraja eglanteria | AR38: 0 | AS38: omitted
A39: 6 | B39: =VLOOKUP(A39,'model groups'!$A$3:$C$86,2,FALSE) -> small sharks and rays | C39: Rhinobatos lentiginosus | D39: RHINOBATOS LENTIGINOSUS | E39: RHINOBATOS LENTIGINOSUS | G39: Chondrichthyes | H39: Rhinobatiformes | I39: Rhinobatidae | J39: Rhinobatos | K39: Atlantic guitarfish | L39: 0.51823347 | N39: 77.49038 | O39: 3.55 | P39: 45.7 | R39: offshore | S39: reef-associated | T39: =IF(OR(AK39=1,AN39=1),"reef","no") -> no | AC39: 0 | AD39: 0 | AE39: 1 | AF39: 1 | AG39: 0 | AH39: 0 | AI39: 0 | AJ39: 0 | AK39: 0 | AL39: 0 | AM39: 1 | AN39: 0 | AO39: 0 | AP39: 0 | AQ39: 0 | AR39: 0 | AS39: omitted
A40: 6 | B40: =VLOOKUP(A40,'model groups'!$A$3:$C$86,2,FALSE) -> small sharks and rays | C40: Sphyrna tiburo | D40: SPHYRNA TIBURO | E40: SPHYRNA TIBURO | G40: Chondrichthyes | H40: Carcharhiniformes | I40: Sphyrnidae | J40: Sphyrna | K40: Bonnethead | L40: 0.45824576 | M40: 4.5093034 | N40: 153.28209 | O40: 3.8466667 | P40: 49.68 | Q40: 1.7744 | R40: nearshore | S40: reef-associated | T40: =IF(OR(AK40=1,AN40=1),"reef","no") -> no | U40: 0.025320506 | V40: 0.80869617 | W40: 0 | X40: 0.079881597 | Y40: 0.084941699 | Z40: 0 | AA40: 0.0011600232 | AB40: 0 | AC40: 1 | AD40: 0 | AE40: 0 | AF40: 1 | AG40: 0 | AH40: 0 | AI40: 0 | AJ40: 0 | AK40: 0 | AL40: 0 | AM40: 1 | AN40: 0 | AO40: 1 | AP40: 0 | AQ40: 1 | AR40: 0 | AS40: omitted
...

Sheet model groups
A1: number | B1: name | C1: min_size_cm | D1: max_size_cm | E1: sedar_spabb | F1: old_num | G1: MICE model name | I1: Old Model Structure | O1: keep | P1: MICE model name | Q1: MICE num | R1: number | S1: name | T1: min_size_cm | U1: max_size_cm | V1: sedar_spabb | W1: old_num | X1: textbox
A2: 1 | B2: offshore dolphins | C2: 0 | D2: 10000 | F2: =VLOOKUP(B2,$J$3:$K$72,2,FALSE) -> #N/A | I2: number | J2: Group name | K2: number | O2: 1 | P2: omitted | Q2: 0 | R2: 99 | S2: not included | T2: 0 | U2: 10000 | W2: #N/A | X2: offshore dolphins, coastal dolphins, seabirds, small sharks and rays, cobia, yellowedge grouper, other DWG, blueline tilefish, golden tilefish, lionfish juv, lionfish adult, gray triggerfish, red porgy, hogfish, black sea bass, mullet, squid, jellyfish, ichthyoplankton, anthozoans, seagrass, macroalgae, not included | AA2: Prey \ predator
A3: =A2+1 -> 2 | B3: coastal dolphins | C3: 0 | D3: 10000 | F3: 1 | I3: 1 | J3: dolphins | K3: 1 | O3: 1 | P3: sharks | Q3: 1 | R3: 5 | S3: large demersal sharks | T3: 0 | U3: 10000 | W3: 3 | X3: pelagic sharks, large demersal sharks | Z3: 1 | AA3: sharks | AB3: 1
A4: =A3+1 -> 3 | B4: seabirds | C4: 0 | D4: 10000 | F4: =VLOOKUP(B4,$J$3:$K$72,2,FALSE) -> 2 | I4: 2 | J4: seabirds | K4: 2 | O4: 1 | P4: pelagic piscivores | Q4: 2 | R4: 52 | S4: coastal piscivores | T4: 0 | U4: 10000 | W4: #N/A | X4: pelagic piscivores, king mackerel juv, king mackerel adult, Spanish mackerel juv, Spanish mackerel adult, coastal piscivores | Z4: 2 | AA4: pelagic piscivores | AB4: 2
A5: =A4+1 -> 4 | B5: pelagic sharks | C5: 0 | D5: 10000 | F5: =VLOOKUP(B5,$J$3:$K$72,2,FALSE) -> #N/A | G5: sharks | I5: 3 | J5: large coastal sharks | K5: 3 | O5: 1 | P5: snappers | Q5: 3 | R5: 19 | S5: other snapper | T5: 0 | U5: 10000 | W5: 17 | X5: red snapper 0, red snapper 1-2, red snapper 3+, vermilion snapper, gray snapper, other snapper | Z5: 3 | AA5: snappers | AB5: 3
A6: =A5+1 -> 5 | B6: large demersal sharks | C6: 0 | D6: 10000 | F6: 3 | G6: sharks | I6: 4 | J6: small coastal sharks | K6: 4 | O6: 1 | P6: gag 0 | Q6: 4 | R6: 20 | S6: gag 0 | T6: 0 | U6: 28 | V6: GAG | W6: 23 | X6: gag 0 | Z6: 4 | AA6: gag 0 | AB6: 4
A7: =A6+1 -> 6 | B7: small sharks and rays | C7: 0 | D7: 10000 | F7: =VLOOKUP(B7,$J$3:$K$72,2,FALSE) -> #N/A | I7: 5 | J7: rays/skates | K7: 5 | O7: 1 | P7: gag 1 | Q7: 5 | R7: 21 | S7: gag 1 | T7: 29 | U7: 39 | V7: GAG | W7: #N/A | X7: gag 1 | Z7: 5 | AA7: gag 1 | AB7: 5
A8: =A7+1 -> 7 | B8: pelagic piscivores | C8: 0 | D8: 10000 | F8: 13 | G8: pelagic piscivores | I8: 6 | J8: billfish & tuna | K8: 6 | O8: 1 | P8: gag 2 | Q8: 6 | R8: 22 | S8: gag 2 | T8: 40 | U8: 48 | V8: GAG | W8: #N/A | X8: gag 2 | Z8: 6 | AA8: gag 2 | AB8: 6
A9: =A8+1 -> 8 | B9: king mackerel juv | C9: 0 | D9: 36 | E9: KMAC | F9: =VLOOKUP(B9,$J$3:$K$72,2,FALSE) -> 9 | G9: pelagic piscivores | I9: 7 | J9: oceanic small pelagics | K9: 7 | O9: 1 | P9: gag 3 | Q9: 7 | R9: 23 | S9: gag 3 | T9: 49 | U9: 57 | V9: GAG | W9: #N/A | X9: gag 3 | Z9: 7 | AA9: gag 3 | AB9: 7
A10: =A9+1 -> 9 | B10: king mackerel adult | C10: 37 | D10: 10000 | E10: KMAC | F10: =VLOOKUP(B10,$J$3:$K$72,2,FALSE) -> 10 | G10: pelagic piscivores | I10: 8 | J10: cobia | K10: 8 | O10: 1 | P10: gag 4 | Q10: 8 | R10: 24 | S10: gag 4 | T10: 58 | U10: 64 | V10: GAG | W10: #N/A | X10: gag 4 | Z10: 8 | AA10: gag 4 | AB10: 8
A11: =A10+1 -> 10 | B11: Spanish mackerel juv | C11: 0 | D11: 24 | E11: SMAC | F11: =VLOOKUP(B11,$J$3:$K$72,2,FALSE) -> 11 | G11: pelagic piscivores | I11: 9 | J11: king Mackerel juv | K11: 9 | O11: 1 | P11: gag 5+ | Q11: 9 | R11: 25 | S11: gag 5+ | T11: 65 | U11: 10000 | V11: GAG | W11: #N/A | X11: gag 5+ | Z11: 9 | AA11: gag 5+ | AB11: 9
A12: =A11+1 -> 11 | B12: Spanish mackerel adult | C12: 25 | D12: 10000 | E12: SMAC | F12: =VLOOKUP(B12,$J$3:$K$72,2,FALSE) -> 12 | G12: pelagic piscivores | I12: 10 | J12: king mackerel adult | K12: 10 | O12: 1 | P12: red grouper 0 | Q12: 10 | R12: 26 | S12: red grouper 0 | T12: 0 | U12: 5 | V12: REDGRP | W12: 26 | X12: red grouper 0 | Z12: 10 | AA12: red grouper 0 | AB12: 10
A13: =A12+1 -> 12 | B13: cobia | C13: 0 | D13: 10000 | E13: COB | F13: =VLOOKUP(B13,$J$3:$K$72,2,FALSE) -> 8 | I13: 11 | J13: Spanish mackerel juv | K13: 11 | O13: 1 | P13: red grouper 1 | Q13: 11 | R13: 27 | S13: red grouper 1 | T13: 6 | U13: 13 | V13: REDGRP | W13: #N/A | X13: red grouper 1 | Z13: 11 | AA13: red grouper 1 | AB13: 11
A14: =A13+1 -> 13 | B14: greater amberjack | C14: 0 | D14: 10000 | E14: GAJ | F14: =VLOOKUP(B14,$J$3:$K$72,2,FALSE) -> #N/A | G14: large reef fish | I14: 12 | J14: Spanish mackerel adult | K14: 12 | O14: 1 | P14: red grouper 2 | Q14: 12 | R14: 28 | S14: red grouper 2 | T14: 14 | U14: 21 | V14: REDGRP | W14: #N/A | X14: red grouper 2 | Z14: 12 | AA14: red grouper 2 | AB14: 12
A15: =A14+1 -> 14 | B15: red snapper 0 | C15: 0 | D15: 13 | E15: RSN | F15: 14 | G15: snappers | I15: 13 | J15: jacks, wahoo, dolphinfish, tunnies | K15: 13 | O15: 1 | P15: red grouper 3 | Q15: 13 | R15: 29 | S15: red grouper 3 | T15: 22 | U15: 27 | V15: REDGRP | W15: #N/A | X15: red grouper 3 | Z15: 13 | AA15: red grouper 3 | AB15: 13
A16: =A15+1 -> 15 | B16: red snapper 1-2 | C16: 21 | D16: 36 | E16: RSN | F16: =VLOOKUP(B16,$J$3:$K$72,2,FALSE) -> #N/A | G16: snappers | I16: 14 | J16: red snapper juv | K16: 14 | O16: 1 | P16: red grouper 4 | Q16: 14 | R16: 30 | S16: red grouper 4 | T16: 28 | U16: 33 | V16: REDGRP | W16: #N/A | X16: red grouper 4 | Z16: 14 | AA16: red grouper 4 | AB16: 14
A17: =A16+1 -> 16 | B17: red snapper 3+ | C17: 37 | D17: 86 | E17: RSN | F17: =VLOOKUP(B17,$J$3:$K$72,2,FALSE) -> #N/A | G17: snappers | I17: 15 | J17: red snapper adult | K17: 15 | O17: 1 | P17: red grouper 5+ | Q17: 15 | R17: 31 | S17: red grouper 5+ | T17: 34 | U17: 10000 | V17: REDGRP | W17: #N/A | X17: red grouper 5+ | Z17: 15 | AA17: red grouper 5+ | AB17: 15
A18: =A17+1 -> 17 | B18: vermilion snapper | C18: 0 | D18: 10000 | E18: VSN | F18: =VLOOKUP(B18,$J$3:$K$72,2,FALSE) -> 16 | G18: snappers | I18: 16 | J18: vermilion snapper | K18: 16 | O18: 1 | P18: large reef fish | Q18: 16 | R18: 36 | S18: other SWG | T18: 0 | U18: 10000 | W18: #N/A | X18: greater amberjack, black grouper, scamp, goliath grouper, other SWG | Z18: 16 | AA18: large reef fish | AB18: 16
A19: =A18+1 -> 18 | B19: gray snapper | C19: 0 | D19: 10000 | E19: GSN | F19: =VLOOKUP(B19,$J$3:$K$72,2,FALSE) -> #N/A | G19: snappers | I19: 17 | J19: other snapper | K19: 17 | O19: 1 | P19: small reef fish | Q19: 17 | R19: 51 | S19: reef planktivores | T19: 0 | U19: 10000 | W19: #N/A | X19: reef carnivores, reef crustacean eaters, reef invertivores, medium reef omnivores, small reef omnivores, reef planktivores | Z19: 17 | AA19: small reef fish | AB19: 17
A20: =A19+1 -> 19 | B20: other snapper | C20: 0 | D20: 10000 | F20: =VLOOKUP(B20,$J$3:$K$72,2,FALSE) -> 17 | G20: snappers | I20: 18 | J20: tilefish | K20: 18 | O20: 1 | P20: demersal fish | Q20: 18 | R20: 55 | S20: demersal omnivores | T20: 0 | U20: 10000 | W20: #N/A | X20: offshore demersal carnivores, nearshore demersal carnivores, demersal omnivores | Z20: 18 | AA20: demersal fish | AB20: 18
A21: =A20+1 -> 20 | B21: gag 0 | C21: 0 | D21: 28 | E21: GAG | F21: 23 | G21: gag 0 | I21: 19 | J21: yellowedge grouper 0-1 | K21: 19 | O21: 1 | P21: small pelagics | Q21: 19 | R21: 58 | S21: offshore small pelagics | T21: 0 | U21: 10000 | W21: #N/A | X21: sardine herring scad, nearshore small pelagics, offshore small pelagics | Z21: 19 | AA21: small pelagics | AB21: 19
A22: =A21+1 -> 21 | B22: gag 1 | C22: =D21+1 -> 29 | D22: 39 | E22: GAG | F22: =VLOOKUP(B22,$J$3:$K$72,2,FALSE) -> #N/A | G22: gag 1 | I22: 20 | J22: yellowedge grouper 1-3 | K22: 20 | O22: 1 | P22: macro-crustaceans | Q22: 20 | R22: 62 | S22: large crabs | T22: 0 | U22: 10000 | W22: 49 | X22: shrimp, large crabs | Z22: 20 | AA22: macro-crustaceans | AB22: 20
A23: =A22+1 -> 22 | B23: gag 2 | C23: =D22+1 -> 40 | D23: 48 | E23: GAG | F23: =VLOOKUP(B23,$J$3:$K$72,2,FALSE) -> #N/A | G23: gag 2 | I23: 21 | J23: yellowedge grouper 3+ | K23: 21 | O23: 1 | P23: micro-crustaceans | Q23: 21 | R23: 68 | S23: mobile epifauna | T23: 0 | U23: 10000 | W23: #N/A | X23: mobile epifauna | Z23: 21 | AA23: micro-crustaceans | AB23: 21
A24: =A23+1 -> 23 | B24: gag 3 | C24: =D23+1 -> 49 | D24: 57 | E24: GAG | F24: =VLOOKUP(B24,$J$3:$K$72,2,FALSE) -> #N/A | G24: gag 3 | I24: 22 | J24: other deep water grouper | K24: 22 | O24: 1 | P24: other invertebrates | Q24: 22 | R24: 71 | S24: microbes | T24: 0 | U24: 10000 | W24: #N/A | X24: stomatopods, echinoderms, gastropods, bivalves, sessile epibenthos, small infauna, meiobenthos, microbes | Z24: 22 | AA24: other invertebrates | AB24: 22
A25: =A24+1 -> 24 | B25: gag 4 | C25: =D24+1 -> 58 | D25: 64 | E25: GAG | F25: =VLOOKUP(B25,$J$3:$K$72,2,FALSE) -> #N/A | G25: gag 4 | I25: 23 | J25: gag 0-1 | K25: 23 | O25: 1 | P25: zooplankton | Q25: 23 | R25: 75 | S25: microzooplankton SZ | T25: 0 | U25: 10000 | W25: #N/A | X25: predatory zooplankton PZ, herbivorous zooplankton LZ, microzooplankton SZ | Z25: 23 | AA25: zooplankton | AB25: 23
A26: =A25+1 -> 25 | B26: gag 5+ | C26: =D25+1 -> 65 | D26: 10000 | E26: GAG | F26: =VLOOKUP(B26,$J$3:$K$72,2,FALSE) -> #N/A | G26: gag 5+ | I26: 24 | J26: gag 1-3 | K26: 24 | O26: 1 | P26: phytoplankton | Q26: 25 | R26: 81 | S26: small phytoplankton SP | T26: 0 | U26: 10000 | W26: #N/A | X26: large phytoplankton LP, small phytoplankton SP | Z26: 24 | AA26: macroalgae | AB26: 24
A27: =A26+1 -> 26 | B27: red grouper 0 | C27: 0 | D27: 5 | E27: REDGRP | F27: 26 | G27: red grouper 0 | I27: 25 | J27: gag 3+ | K27: 25 | O27: 1 | P27: detritus | Q27: 26 | R27: 83 | S27: sediment detritus | T27: 0 | U27: 10000 | W27: 69 | X27: water column detritus, sediment detritus | Z27: 25 | AA27: phytoplankton | AB27: 25
A28: =A27+1 -> 27 | B28: red grouper 1 | C28: =D27+1 -> 6 | D28: 13 | E28: REDGRP | F28: =VLOOKUP(B28,$J$3:$K$72,2,FALSE) -> #N/A | G28: red grouper 1 | I28: 26 | J28: red grouper 0-1 | K28: 26 | O28: 0 | P28: omitted | Q28: 0 | R28: 1 | S28: offshore dolphins | T28: 0 | U28: 10000 | W28: #N/A | X28: offshore dolphins | Z28: 26 | AA28: detritus | AB28: 26
A29: =A28+1 -> 28 | B29: red grouper 2 | C29: =D28+1 -> 14 | D29: 21 | E29: REDGRP | F29: =VLOOKUP(B29,$J$3:$K$72,2,FALSE) -> #N/A | G29: red grouper 2 | I29: 27 | J29: red grouper 1-3 | K29: 27 | O29: 0 | P29: omitted | Q29: 0 | R29: 2 | S29: coastal dolphins | T29: 0 | U29: 10000 | W29: 1 | X29: offshore dolphins, coastal dolphins
A30: =A29+1 -> 29 | B30: red grouper 3 | C30: =D29+1 -> 22 | D30: 27 | E30: REDGRP | F30: =VLOOKUP(B30,$J$3:$K$72,2,FALSE) -> #N/A | G30: red grouper 3 | I30: 28 | J30: red grouper 3+ | K30: 28 | O30: 0 | P30: omitted | Q30: 0 | R30: 3 | S30: seabirds | T30: 0 | U30: 10000 | W30: 2 | X30: offshore dolphins, coastal dolphins, seabirds
A31: =A30+1 -> 30 | B31: red grouper 4 | C31: =D30+1 -> 28 | D31: 33 | E31: REDGRP | F31: =VLOOKUP(B31,$J$3:$K$72,2,FALSE) -> #N/A | G31: red grouper 4 | I31: 29 | J31: black grouper 0-1 | K31: 29 | O31: 0 | P31: omitted | Q31: 0 | R31: 6 | S31: small sharks and rays | T31: 0 | U31: 10000 | W31: #N/A | X31: offshore dolphins, coastal dolphins, seabirds, small sharks and rays
A32: =A31+1 -> 31 | B32: red grouper 5+ | C32: =D31+1 -> 34 | D32: 10000 | E32: REDGRP | F32: =VLOOKUP(B32,$J$3:$K$72,2,FALSE) -> #N/A | G32: red grouper 5+ | I32: 30 | J32: black grouper 1-3 | K32: 30 | O32: 0 | P32: omitted | Q32: 0 | R32: 12 | S32: cobia | T32: 0 | U32: 10000 | V32: COB | W32: 8 | X32: offshore dolphins, coastal dolphins, seabirds, small sharks and rays, cobia
A33: =A32+1 -> 32 | B33: black grouper | C33: 0 | D33: 10000 | F33: =VLOOKUP(B33,$J$3:$K$72,2,FALSE) -> #N/A | G33: large reef fish | I33: 31 | J33: black grouper 3+ | K33: 31 | O33: 0 | P33: omitted | Q33: 0 | R33: 33 | S33: yellowedge grouper | T33: 0 | U33: 10000 | V33: YEG | W33: #N/A | X33: offshore dolphins, coastal dolphins, seabirds, small sharks and rays, cobia, yellowedge grouper
A34: =A33+1 -> 33 | B34: yellowedge grouper | C34: 0 | D34: 10000 | E34: YEG | F34: =VLOOKUP(B34,$J$3:$K$72,2,FALSE) -> #N/A | I34: 32 | J34: other shallow water grouper | K34: 32 | O34: 0 | P34: omitted | Q34: 0 | R34: 37 | S34: other DWG | T34: 0 | U34: 10000 | W34: #N/A | X34: offshore dolphins, coastal dolphins, seabirds, small sharks and rays, cobia, yellowedge grouper, other DWG
A35: =A34+1 -> 34 | B35: scamp | C35: 0 | D35: 10000 | E35: SCAMP | F35: =VLOOKUP(B35,$J$3:$K$72,2,FALSE) -> #N/A | G35: large reef fish | I35: 33 | J35: goliath grouper | K35: 33 | O35: 0 | P35: omitted | Q35: 0 | R35: 38 | S35: blueline tilefish | T35: 0 | U35: 10000 | W35: #N/A | X35: offshore dolphins, coastal dolphins, seabirds, small sharks and rays, cobia, yellowedge grouper, other DWG, blueline tilefish
A36: =A35+1 -> 35 | B36: goliath grouper | C36: 0 | D36: 10000 | F36: =VLOOKUP(B36,$J$3:$K$72,2,FALSE) -> 33 | G36: large reef fish | I36: 34 | J36: triggerfish | K36: 34 | O36: 0 | P36: omitted | Q36: 0 | R36: 39 | S36: golden tilefish | T36: 0 | U36: 10000 | V36: TLF | W36: #N/A | X36: offshore dolphins, coastal dolphins, seabirds, small sharks and rays, cobia, yellowedge grouper, other DWG, blueline tilefish, golden tilefish
A37: =A36+1 -> 36 | B37: other SWG | C37: 0 | D37: 10000 | F37: =VLOOKUP(B37,$J$3:$K$72,2,FALSE) -> #N/A | G37: large reef fish | I37: 35 | J37: amberjack | K37: 35 | O37: 0 | P37: omitted | Q37: 0 | R37: 40 | S37: lionfish juv | T37: 0 | U37: 15 | W37: #N/A | X37: offshore dolphins, coastal dolphins, seabirds, small sharks and rays, cobia, yellowedge grouper, other DWG, blueline tilefish, golden tilefish, lionfish juv
A38: =A37+1 -> 37 | B38: other DWG | C38: 0 | D38: 10000 | F38: =VLOOKUP(B38,$J$3:$K$72,2,FALSE) -> #N/A | I38: 36 | J38: black sea bass | K38: 36 | O38: 0 | P38: omitted | Q38: 0 | R38: 41 | S38: lionfish adult | T38: 16 | U38: 42 | W38: #N/A | X38: offshore dolphins, coastal dolphins, seabirds, small sharks and rays, cobia, yellowedge grouper, other DWG, blueline tilefish, golden tilefish, lionfish juv, lionfish adult
A39: =A38+1 -> 38 | B39: blueline tilefish | C39: 0 | D39: 10000 | F39: =VLOOKUP(B39,$J$3:$K$72,2,FALSE) -> #N/A | I39: 37 | J39: reef carnivores (grunt, porgy, wrasse, perch) | K39: 37 | O39: 0 | P39: omitted | Q39: 0 | R39: 42 | S39: gray triggerfish | T39: 0 | U39: 10000 | V39: GTF | W39: #N/A | X39: offshore dolphins, coastal dolphins, seabirds, small sharks and rays, cobia, yellowedge grouper, other DWG, blueline tilefish, golden tilefish, lionfish juv, lionfish adult, gray triggerfish
A40: =A39+1 -> 39 | B40: golden tilefish | C40: 0 | D40: 10000 | E40: TLF | F40: =VLOOKUP(B40,$J$3:$K$72,2,FALSE) -> #N/A | I40: 38 | J40: reef omnivores (angelfish, surgeonfish, chub) | K40: 38 | O40: 0 | P40: omitted | Q40: 0 | R40: 43 | S40: red porgy | T40: 0 | U40: 10000 | W40: #N/A | X40: offshore dolphins, coastal dolphins, seabirds, small sharks and rays, cobia, yellowedge grouper, other DWG, blueline tilefish, golden tilefish, lionfish juv, lionfish adult, gray triggerfish, red porgy
...

Sheet Sheet1
E3: MICE num | F3: MICE name | G3: WFS-FEM functional groups | L3: Fleet\group | M3: recreational | N3: commercial reef | O3: shrimp fishery | P3: other | Q3: commercial VL gag | R3: commercial LL gag | S3: recreational headboat gag | T3: recreational charter gag | U3: recreational private shore gag | V3: commercial HL red | W3: commercial LL red | X3: commercial trap red | Y3: recreational red
E4: 1 | F4: sharks | G4: pelagic sharks, large demersal sharks | K4: 1 | L4: sharks | M4: 0.01674659 | N4: 0.06538093 | O4: 0.009641051 | P4: 0.02979952
E5: 2 | F5: pelagic piscivores | G5: pelagic piscivores, king mackerel juv, king mackerel adult, Spanish mackerel juv, Spanish mackerel adult, coastal piscivores | K5: 2 | L5: pelagic piscivores | M5: 0.1168813 | N5: 0.009688121 | O5: 0.0005401551 | P5: 0.05622274
E6: 3 | F6: snappers | G6: red snapper 0, red snapper 1-2, red snapper 3+, vermilion snapper, gray snapper, other snapper | K6: 3 | L6: snappers | M6: 0.04138286 | N6: 0.02450651 | O6: 0.000305989 | P6: 1.492829e-06
E7: 4 | F7: gag 0 | G7: gag 0 | K7: 4 | L7: gag 0 | S7: 0.0003018486 | U7: 0.02530658
E8: 5 | F8: gag 1 | G8: gag 1 | K8: 5 | L8: gag 1 | Q8: 0.001218002 | R8: 1.118426e-05 | S8: 0.008553988 | T8: 0.0103777 | U8: 0.03185689
E9: 6 | F9: gag 2 | G9: gag 2 | K9: 6 | L9: gag 2 | Q9: 0.006448403 | R9: 0.0001098072 | S9: 0.02168537 | T9: 0.03145899 | U9: 0.04265808
E10: 7 | F10: gag 3 | G10: gag 3 | K10: 7 | L10: gag 3 | Q10: 0.0148782 | R10: 0.0004877671 | S10: 0.0223279 | T10: 0.03631884 | U10: 0.03345755
E11: 8 | F11: gag 4 | G11: gag 4 | K11: 8 | L11: gag 4 | Q11: 0.05596825 | R11: 0.003600765 | S11: 0.04406751 | T11: 0.07737648 | U11: 0.06069049
E12: 9 | F12: gag 5+ | G12: gag 5+ | K12: 9 | L12: gag 5+ | Q12: 0.09531402 | R12: 0.02016845 | S12: 0.02114886 | T12: 0.03914309 | U12: 0.02123453
E13: 10 | F13: red grouper 0 | G13: red grouper 0 | K13: 10 | L13: red grouper 0 | V13: 7.72469e-07 | W13: 0.0002864641 | Y13: 1.61374e-05
E14: 11 | F14: red grouper 1 | G14: red grouper 1 | K14: 11 | L14: red grouper 1 | V14: 2.662723e-05 | W14: 0.0007960735 | X14: 0.000938223 | Y14: 0.001230682
E15: 12 | F15: red grouper 2 | G15: red grouper 2 | K15: 12 | L15: red grouper 2 | V15: 0.0003444853 | W15: 0.001605299 | X15: 0.003362022 | Y15: 0.01237702
E16: 13 | F16: red grouper 3 | G16: red grouper 3 | K16: 13 | L16: red grouper 3 | V16: 0.003117135 | W16: 0.004308545 | X16: 0.007821109 | Y16: 0.05441364
E17: 14 | F17: red grouper 4 | G17: red grouper 4 | K17: 14 | L17: red grouper 4 | V17: 0.01633303 | W17: 0.01171835 | X17: 0.01233838 | Y17: 0.09303208
E18: 15 | F18: red grouper 5+ | G18: red grouper 5+ | K18: 15 | L18: red grouper 5+ | V18: 0.05673439 | W18: 0.0390414 | X18: 0.01316659 | Y18: 0.05920526
E19: 16 | F19: large reef fish | G19: greater amberjack, black grouper, scamp, goliath grouper, other SWG | K19: 16 | L19: large reef fish | M19: 0.195461 | N19: 0.02581763 | O19: 0.02830131
E20: 17 | F20: small reef fish | G20: reef carnivores, reef crustacean eaters, reef invertivores, medium reef omnivores, small reef omnivores, reef planktivores
E21: 18 | F21: demersal fish | G21: offshore demersal carnivores, nearshore demersal carnivores, demersal omnivores
E22: 19 | F22: small pelagics | G22: sardine herring scad, nearshore small pelagics, offshore small pelagics
E23: 20 | F23: macro-crustaceans | G23: shrimp, large crabs
E24: 21 | F24: micro-crustaceans | G24: mobile epifauna
E25: 22 | F25: other invertebrates | G25: stomatopods, echinoderms, gastropods, bivalves, sessile epibenthos, small infauna, meiobenthos, microbes
E26: 23 | F26: zooplankton | G26: predatory zooplankton PZ, herbivorous zooplankton LZ, microzooplankton SZ
E27: 25 | F27: phytoplankton | G27: large phytoplankton LP, small phytoplankton SP
E28: 26 | F28: detritus | G28: water column detritus, sediment detritus
E29: 0 | F29: omitted | G29: offshore dolphins, coastal dolphins, seabirds, small sharks and rays, cobia, yellowedge grouper, other DWG, blueline tilefish, golden tilefish, lionfish juv, lionfish adult, gray triggerfish, red porgy, hogfish, black sea bass, mullet, squid, jellyfish, ichthyoplankton, anthozoans, seagrass, macroalgae, not included

Sheet spp_stanzas_sizes
A1: sciname | B1: common | C1: spabb | D1: stanzas | E1: fg | F1: age0 | G1: age1 | H1: age2 | I1: age3 | J1: age4 | K1: age5 | L1: age6 | M1: age7 | N1: age8 | O1: age9 | P1: fg_mice
A2: Rachycentron canadum | B2: cobia | C2: COB | D2: 0 | E2: 12 | F2: 6 | G2: 43.2877 | H2: 72.3743 | I2: 91.4856 | J2: 104.043 | K2: 112.293 | L2: 117.714 | M2: 121.276 | N2: 123.616 | O2: 125.154 | P2: 0
A3: Mycteroperca microlepis | B3: gag | C3: GAG | D3: 0-1-2-3-4-5 | E3: 20-21-22-23-24-25 | F3: 10 | G3: 28.2087 | H3: 39.1672 | I3: 48.8155 | J3: 57.3105 | K3: 64.7898 | L3: 71.3749 | M3: 77.1728 | N3: 82.2775 | O3: 86.772 | P3: 4-5-6-7-8-9
A4: Seriola dumerili | B4: greater amberjack | C4: GAJ | D4: 0 | E4: 13 | F4: 10 | G4: 26.3671 | H4: 47.4423 | I4: 64.2606 | J4: 77.6817 | K4: 88.392 | L4: 96.9389 | M4: 103.759 | N4: 109.202 | O4: 113.546 | P4: 0
A5: Lutjanus griseus | B5: gray snapper | C5: GSN | D5: 0 | E5: 18 | F5: 2 | G5: 16.7076 | H5: 21.4189 | I5: 25.6267 | J5: 29.385 | K5: 32.7416 | L5: 35.7397 | M5: 38.4173 | N5: 40.8089 | O5: 42.945 | P5: 0
A6: Balistes capriscus | B6: gray triggerfish | C6: GTF | D6: 0 | E6: 42 | F6: 4 | G6: 30.3735 | H6: 34.1094 | I6: 37.3572 | J6: 40.1807 | K6: 42.6354 | L6: 44.7694 | M6: 46.6246 | N6: 48.2374 | O6: 49.6395 | P6: 0
A7: Scomberomorus cavalla | B7: king mackerel | C7: KMAC | D7: 0-1 | E7: 8-9 | F7: 10 | G7: 36.046 | H7: 58.7304 | I7: 74.1989 | J7: 84.7469 | K7: 91.9396 | L7: 96.8442 | M7: 100.189 | N7: 102.469 | O7: 104.024 | P7: 0
A8: Epinephelus morio | B8: red grouper | C8: REDGRP | D8: 0-1-2-3-4-5 | E8: 26-27-28-29-30-31 | F8: 2 | G8: 5.01618 | H8: 13.5746 | I8: 21.1562 | J8: 27.8724 | K8: 33.8219 | L8: 39.0924 | M8: 43.7612 | N8: 47.8971 | O8: 51.5609 | P8: 10-11-12-13-14-15
A9: Lutjanus campechanus | B9: red snapper | C9: RSN | D9: 0-1-3 | E9: 14-15-16 | F9: 8 | G9: 13.505 | H9: 26.1006 | I9: 36.4968 | J9: 45.0777 | K9: 52.1603 | L9: 58.0062 | M9: 62.8314 | N9: 66.814 | O9: 70.1012 | P9: 0
A10: Mycteroperca phenax | B10: scamp | C10: SCAMP | D10: 0 | E10: 34 | F10: 6 | G10: 18.7859 | H10: 29.0593 | I10: 37.7623 | J10: 45.1348 | K10: 51.3803 | L10: 56.671 | M10: 61.153 | N10: 64.9498 | O10: 68.1662 | P10: 0
A11: Scomberomorus maculatus | B11: spanish mackerel | C11: SMAC | D11: 0-1 | E11: 10-11 | F11: 3 | G11: 24.6953 | H11: 28.3812 | I11: 31.8088 | J11: 34.9962 | K11: 37.9602 | L11: 40.7165 | M11: 43.2796 | N11: 45.6631 | O11: 47.8796 | P11: 0
A12: Lopholatilus chamaeleonticeps | B12: golden tilefish | C12: TLF | D12: 0 | E12: 39 | F12: 4 | G12: 18.8761 | H12: 32.0775 | I12: 40.8978 | J12: 46.791 | K12: 50.7284 | L12: 53.3592 | M12: 55.1169 | N12: 56.2913 | O12: 57.076 | P12: 0
A13: Rhomboplites aurorubens | B13: vermilion snapper | C13: VSN | D13: 0 | E13: 17 | F13: 1.4 | G13: 10.1842 | H13: 17.9647 | I13: 24.8564 | J13: 30.9606 | K13: 36.3675 | L13: 41.1566 | M13: 45.3986 | N13: 49.1559 | O13: 52.4839 | P13: 0
A14: Epinephelus flavolimbatus | B14: yellowedge grouper | C14: YEG | D14: 0 | E14: 33 | F14: 1 | G14: 15.219 | H14: 20.5467 | I14: 24.3946 | J14: 27.1737 | K14: 29.1809 | L14: 30.6306 | M14: 31.6776 | N14: 32.4338 | O14: 32.9799 | P14: 0
A15: Ocyurus chrysurus | B15: yellowtail snapper | C15: YTS | D15: 0 | E15: 99 | F15: 5 | G15: 11.6493 | H15: 17.7883 | I15: 23.4562 | J15: 28.6892 | K15: 33.5206 | L15: 37.9813 | M15: 42.0996 | N15: 45.902 | O15: 49.4126 | P15: 0
C16: NA | D16: NA | F16: 5.70702 | G16: 14.3569 | H16: 20.586 | I16: 25.0718 | J16: 28.3022 | K16: 30.6285 | L16: 32.3038 | M16: 33.5103 | N16: 34.3791 | O16: 35.0047 | P16: 0

Sheet cluster spp
A1: cluster | B1: modnumber | C1: clusname | D1: FBname | E1: sciname | F1: class | G1: family | H1: Genus | I1: Species | J1: M | K1: QB | L1: Lmax | M1: TL | N1: Vul | O1: AR | P1: fish | Q1: benthcrust | R1: detritus | S1: plants | T1: cephalopods | U1: cnidarians | V1: otherinverts | W1: zooplankton | X1: NearOff | Y1: DemPel | Z1: class.1 | AA1: softbottom | AB1: hardbottom | AC1: veg | AD1: coral
A2: 3 | B2: =LOOKUP(A2,'cluster stats'!$B$21:$B$35,'cluster stats'!$A$21:$A$35) -> 4 | C2: =VLOOKUP(A2,'cluster stats'!$A$2:$B$16,2,FALSE) -> pelagic sharks | D2: Gulf smoothhound | E2: Mustelus sinusmexicanus | F2: Chondrichthyes | G2: Triakidae | H2: Mustelus | I2: sinusmexicanus | J2: 0.4859777 | K2: 5.0075481 | L2: 85.617935 | M2: 3.755 | N2: 63.38 | O2: 1.0128385 | P2: 0.10079856 | Q2: 0.77477465 | R2: 0.012256968 | S2: 0 | T2: 0.015142641 | U2: 0 | V2: 0.095912915 | W2: 0.0011142698 | X2: offshore | Y2: pelagic | Z2: Chondrichthyes | AA2: 1 | AB2: 0 | AC2: 0 | AD2: 0
A3: 4 | B3: =LOOKUP(A3,'cluster stats'!$B$21:$B$35,'cluster stats'!$A$21:$A$35) -> 4 | C3: =VLOOKUP(A3,'cluster stats'!$A$2:$B$16,2,FALSE) -> pelagic sharks | D3: Sandbar shark | E3: Carcharhinus plumbeus | F3: Chondrichthyes | G3: Carcharhinidae | H3: Carcharhinus | I3: plumbeus | J3: 0.1575 | K3: 3.5002132 | L3: 183.40606 | M3: 4.34 | N3: 87.51 | O3: 3.178275 | P3: 0.85768577 | Q3: 0.084341765 | R3: 0.0055005502 | S3: 0.00033336668 | T3: 0.046771345 | U3: 0 | V3: 0.0039670634 | W3: 0.00140014 | X3: nearshore | Y3: pelagic | Z3: Chondrichthyes | AA3: 1 | AB3: 0 | AC3: 0 | AD3: 1
A4: 4 | B4: =LOOKUP(A4,'cluster stats'!$B$21:$B$35,'cluster stats'!$A$21:$A$35) -> 4 | C4: =VLOOKUP(A4,'cluster stats'!$A$2:$B$16,2,FALSE) -> pelagic sharks | D4: Tiger shark | E4: Galeocerdo cuvier | F4: Chondrichthyes | G4: Carcharhinidae | H4: Galeocerdo | I4: cuvier | J4: 0.16071429 | K4: 1.0339962 | L4: 747.04676 | M4: 4.53 | N4: 63.83 | O4: 1.385944 | P4: 0.87132141 | Q4: 0.070398152 | R4: 0.024235429 | S4: 0 | T4: 0.027697635 | U4: 0 | V4: 0.0063473747 | W4: 0 | X4: nearshore | Y4: pelagic | Z4: Chondrichthyes | AA4: 0 | AB4: 0 | AC4: 0 | AD4: 1
A5: 4 | B5: =LOOKUP(A5,'cluster stats'!$B$21:$B$35,'cluster stats'!$A$21:$A$35) -> 4 | C5: =VLOOKUP(A5,'cluster stats'!$A$2:$B$16,2,FALSE) -> pelagic sharks | D5: Scalloped hammerhead | E5: Sphyrna lewini | F5: Chondrichthyes | G5: Sphyrnidae | H5: Sphyrna | I5: lewini | J5: 0.19644867 | K5: 1.8266731 | L5: 432.11198 | M5: 4.0966667 | N5: 81.26 | O5: 1.80809 | P5: 0.75723237 | Q5: 0.18977469 | R5: 0 | S5: 0.00099986671 | T5: 0.051659778 | U5: 0 | V5: 0.00033328889 | W5: 0 | X5: nearshore | Y5: pelagic | Z5: Chondrichthyes | AA5: 0 | AB5: 0 | AC5: 0 | AD5: 1
A6: 4 | B6: =LOOKUP(A6,'cluster stats'!$B$21:$B$35,'cluster stats'!$A$21:$A$35) -> 4 | C6: =VLOOKUP(A6,'cluster stats'!$A$2:$B$16,2,FALSE) -> pelagic sharks | D6: Great hammerhead | E6: Sphyrna mokarran | F6: Chondrichthyes | G6: Sphyrnidae | H6: Sphyrna | I6: mokarran | J6: 0.15 | K6: 1.7045037 | L6: 609.59738 | M6: 4.3266667 | N6: 86.03 | O6: 1.85353 | P6: 0.853 | Q6: 0.112 | R6: 0 | S6: 0.002 | T6: 0.033 | U6: 0 | V6: 0 | W6: 0 | X6: nearshore | Y6: pelagic | Z6: Chondrichthyes | AA6: 0 | AB6: 0 | AC6: 0 | AD6: 0
A7: 2 | B7: =LOOKUP(A7,'cluster stats'!$B$21:$B$35,'cluster stats'!$A$21:$A$35) -> 5 | C7: =VLOOKUP(A7,'cluster stats'!$A$2:$B$16,2,FALSE) -> large demersal sharks | D7: Blacknose shark | E7: Carcharhinus acronotus | F7: Chondrichthyes | G7: Carcharhinidae | H7: Carcharhinus | I7: acronotus | J7: 0.73346285 | K7: 3.6548582 | L7: 103.6 | M7: 4.3233333 | N7: 69.76 | O7: 1.82749 | P7: 0.982 | Q7: 0.012000001 | R7: 0 | S7: 0 | T7: 0 | U7: 0 | V7: 0.0060000004 | W7: 0 | X7: offshore | Y7: reef-associated | Z7: Chondrichthyes | AA7: 0 | AB7: 0 | AC7: 0 | AD7: 0
A8: 2 | B8: =LOOKUP(A8,'cluster stats'!$B$21:$B$35,'cluster stats'!$A$21:$A$35) -> 5 | C8: =VLOOKUP(A8,'cluster stats'!$A$2:$B$16,2,FALSE) -> large demersal sharks | D8: Spinner shark | E8: Carcharhinus brevipinna | F8: Chondrichthyes | G8: Carcharhinidae | H8: Carcharhinus | I8: brevipinna | J8: 0.34652701 | K8: 6.319572 | L8: 214 | M8: 4.28 | N8: 62.25 | O8: 5.87939 | P8: 0.911 | Q8: 0.02 | R8: 0 | S8: 0.01 | T8: 0.059000002 | U8: 0 | V8: 0 | W8: 0 | X8: offshore | Y8: reef-associated | Z8: Chondrichthyes | AA8: 0 | AB8: 0 | AC8: 0 | AD8: 0
A9: 2 | B9: =LOOKUP(A9,'cluster stats'!$B$21:$B$35,'cluster stats'!$A$21:$A$35) -> 5 | C9: =VLOOKUP(A9,'cluster stats'!$A$2:$B$16,2,FALSE) -> large demersal sharks | D9: Silky shark | E9: Carcharhinus falciformis | F9: Chondrichthyes | G9: Carcharhinidae | H9: Carcharhinus | I9: falciformis | J9: 0.25935608 | K9: 2.0817524 | L9: 352.87213 | M9: 4.4766667 | N9: 79.03 | O9: 2.02629 | P9: 0.607 | Q9: 0.017 | R9: 0.050999998 | S9: 0 | T9: 0.3095 | U9: 0 | V9: 0.015499999 | W9: 0 | X9: offshore | Y9: reef-associated | Z9: Chondrichthyes | AA9: 0 | AB9: 0 | AC9: 0 | AD9: 0
A10: 2 | B10: =LOOKUP(A10,'cluster stats'!$B$21:$B$35,'cluster stats'!$A$21:$A$35) -> 5 | C10: =VLOOKUP(A10,'cluster stats'!$A$2:$B$16,2,FALSE) -> large demersal sharks | D10: Bull shark | E10: Carcharhinus leucas | F10: Chondrichthyes | G10: Carcharhinidae | H10: Carcharhinus | I10: leucas | J10: 0.21678143 | K10: 2.3837994 | L10: 362.79166 | M10: 4.2866667 | N10: 87.54 | O10: 1.44355 | P10: 0.9231579 | Q10: 0.02736842 | R10: 0 | S10: 0.042105263 | T10: 0.0052631579 | U10: 0 | V10: 0.0021052632 | W10: 0 | X10: nearshore | Y10: reef-associated | Z10: Chondrichthyes | AA10: 0 | AB10: 0 | AC10: 0 | AD10: 0
A11: 2 | B11: =LOOKUP(A11,'cluster stats'!$B$21:$B$35,'cluster stats'!$A$21:$A$35) -> 5 | C11: =VLOOKUP(A11,'cluster stats'!$A$2:$B$16,2,FALSE) -> large demersal sharks | D11: Blacktip shark | E11: Carcharhinus limbatus | F11: Chondrichthyes | G11: Carcharhinidae | H11: Carcharhinus | I11: limbatus | J11: 0.43089197 | K11: 3.5664409 | L11: 176 | M11: 4.3266667 | N11: 55.45 | O11: 2.000455 | P11: 0.95108422 | Q11: 0.01260716 | R11: 0 | S11: 0.00050428643 | T11: 0.034291477 | U11: 0 | V11: 0.0015128593 | W11: 0 | X11: nearshore | Y11: reef-associated | Z11: Chondrichthyes | AA11: 0 | AB11: 0 | AC11: 0 | AD11: 0
A12: 2 | B12: =LOOKUP(A12,'cluster stats'!$B$21:$B$35,'cluster stats'!$A$21:$A$35) -> 5 | C12: =VLOOKUP(A12,'cluster stats'!$A$2:$B$16,2,FALSE) -> large demersal sharks | D12: Nurse shark | E12: Ginglymostoma cirratum | F12: Chondrichthyes | G12: Ginglymostomatidae | H12: Ginglymostoma | I12: cirratum | J12: 0.14401438 | K12: 2.2625714 | L12: 432.11198 | M12: 4.0733333 | N12: 81.38 | O12: 1.65 | P12: 0.38 | Q12: 0.18533333 | R12: 0 | S12: 0 | T12: 0.138 | U12: 0 | V12: 0.29666667 | W12: 0 | X12: nearshore | Y12: reef-associated | Z12: Chondrichthyes | AA12: 1 | AB12: 0 | AC12: 0 | AD12: 1
A13: 1 | B13: =LOOKUP(A13,'cluster stats'!$B$21:$B$35,'cluster stats'!$A$21:$A$35) -> 6 | C13: =VLOOKUP(A13,'cluster stats'!$A$2:$B$16,2,FALSE) -> small sharks and rays | D13: Finetooth shark | E13: Carcharhinus isodon | F13: Chondrichthyes | G13: Carcharhinidae | H13: Carcharhinus | I13: isodon | J13: 0.55900621 | K13: 3.0532243 | L13: 193.42893 | M13: 4.25 | N13: 60.19 | O13: 2.56489 | P13: 0.959 | Q13: 0 | R13: 0 | S13: 0 | T13: 0 | U13: 0 | V13: 0.040999998 | W13: 0 | X13: offshore | Y13: demersal | Z13: Chondrichthyes | AA13: 0 | AB13: 0 | AC13: 0 | AD13: 0
... A80: 7 | B80: =LOOKUP(A80,'cluster stats'!$B$21:$B$35,'cluster stats'!$A$21:$A$35) -> 47 | C80: =VLOOKUP(A80,'cluster stats'!$A$2:$B$16,2,FALSE) -> reef invertivores | D80: Fringed filefish | E80: Monacanthus ciliatus | F80: Teleostei | G80: Monacanthidae | H80: Monacanthus | I80: ciliatus | J80: 1.1981004 | K80: 15.433012 | L80: 21.102972 | M80: 2.8733334 | N80: 27.34 | O80: 1.45086 | P80: 0 | Q80: 0.17366946 | R80: 0 | S80: 0.37444978 | T80: 0 | U80: 0 | V80: 0.081732693 | W80: 0.37014806 | X80: offshore | Y80: reef-associated | Z80: Teleostei | AA80: 0 | AB80: 0 | AC80: 0 | AD80: 0
A81: 7 | B81: =LOOKUP(A81,'cluster stats'!$B$21:$B$35,'cluster stats'!$A$21:$A$35) -> 47 | C81: =VLOOKUP(A81,'cluster stats'!$A$2:$B$16,2,FALSE) -> reef invertivores | D81: Ogcocephalus cubifrons | E81: Ogcocephalus cubifrons | F81: Teleostei | G81: #N/A | H81: Ogcocephalus | I81: cubifrons | J81: 0.79753165 | K81: 7.6319174 | L81: 39.688532 | M81: 3.47 | N81: 57.68 | O81: 1.65 | P81: 0.088000002 | Q81: 0.481 | R81: 0 | S81: 0.111 | T81: 0 | U81: 0 | V81: 0.32 | W81: 0 | X81: offshore | Y81: reef-associated | Z81: Teleostei | AA81: 1 | AB81: 0 | AC81: 0 | AD81: 0
A82: 7 | B82: =LOOKUP(A82,'cluster stats'!$B$21:$B$35,'cluster stats'!$A$21:$A$35) -> 47 | C82: =VLOOKUP(A82,'cluster stats'!$A$2:$B$16,2,FALSE) -> reef invertivores | D82: Gray angelfish | E82: Pomacanthus arcuatus | F82: Teleostei | G82: Pomacanthidae | H82: Pomacanthus | I82: arcuatus | J82: 0.59699652 | K82: 6.5236631 | L82: 62.212642 | M82: 3.0666667 | N82: 51.36 | O82: 2.06313 | P82: 0 | Q82: 0.00033333334 | R82: 0.016333333 | S82: 0.18463333 | T82: 0 | U82: 0.025166667 | V82: 0.72653333 | W82: 0.047000002 | X82: offshore | Y82: reef-associated | Z82: Teleostei | AA82: 0 | AB82: 0 | AC82: 0 | AD82: 1
A83: 7 | B83: =LOOKUP(A83,'cluster stats'!$B$21:$B$35,'cluster stats'!$A$21:$A$35) -> 47 | C83: =VLOOKUP(A83,'cluster stats'!$A$2:$B$16,2,FALSE) -> reef invertivores | D83: Planehead filefish | E83: Stephanolepis hispidus | F83: Teleostei | G83: Monacanthidae | H83: Stephanolepis | I83: hispidus | J83: 0.97904265 | K83: 13.534045 | L83: 28.870035 | M83: 2.53 | N83: 29.59 | O83: 1.26543 | P83: 0 | Q83: 0.02779861 | R83: 0.49287536 | S83: 0.069446531 | T83: 0 | U83: 0 | V83: 0.4098795 | W83: 0 | X83: offshore | Y83: reef-associated | Z83: Teleostei | AA83: 1 | AB83: 0 | AC83: 1 | AD83: 0
A84: 7 | B84: =LOOKUP(A84,'cluster stats'!$B$21:$B$35,'cluster stats'!$A$21:$A$35) -> 47 | C84: =VLOOKUP(A84,'cluster stats'!$A$2:$B$16,2,FALSE) -> reef invertivores | D84: Spottedfin tonguefish | E84: Symphurus diomedeanus | F84: Teleostei | G84: Cynoglossidae | H84: Symphurus | I84: diomedeanus | J84: 1.1278412 | K84: 13.162612 | L84: 23.178118 | M84: 3.29 | N84: 26.82 | O84: 1.65 | P84: 0 | Q84: 0.26 | R84: 0 | S84: 0.19 | T84: 0 | U84: 0 | V84: 0.51 | W84: 0.04 | X84: offshore | Y84: reef-associated | Z84: Teleostei | AA84: 1 | AB84: 0 | AC84: 0 | AD84: 0
A85: 7 | B85: =LOOKUP(A85,'cluster stats'!$B$21:$B$35,'cluster stats'!$A$21:$A$35) -> 47 | C85: =VLOOKUP(A85,'cluster stats'!$A$2:$B$16,2,FALSE) -> reef invertivores | D85: Offshore lizardfish | E85: Synodus poeyi | F85: Teleostei | G85: Synodontidae | H85: Synodus | I85: poeyi | J85: 1.0400324 | K85: 8.511429 | L85: 26.285289 | M85: 4.535 | N85: 18.94 | O85: 1.35076 | P85: 0.025000001 | Q85: 0.013 | R85: 0 | S85: 0 | T85: 0 | U85: 0 | V85: 0.962 | W85: 0 | X85: offshore | Y85: reef-associated | Z85: Teleostei | AA85: 0 | AB85: 0 | AC85: 0 | AD85: 0
A86: 7 | B86: =LOOKUP(A86,'cluster stats'!$B$21:$B$35,'cluster stats'!$A$21:$A$35) -> 47 | C86: =VLOOKUP(A86,'cluster stats'!$A$2:$B$16,2,FALSE) -> reef invertivores | D86: Pearly razorfish | E86: Xyrichtys novacula | F86: Teleostei | G86: Labridae | H86: Xyrichtys | I86: novacula | J86: 0.80830035 | K86: 7.3079946 | L86: 39.688532 | M86: 3.445 | N86: 36.27 | O86: 1.37048 | P86: 0.0075 | Q86: 0.1025 | R86: 0.031500001 | S86: 0 | T86: 0 | U86: 0 | V86: 0.842 | W86: 0.0165 | X86: offshore | Y86: reef-associated | Z86: Teleostei | AA86: 1 | AB86: 0 | AC86: 1 | AD86: 1
A87: 5 | B87: =LOOKUP(A87,'cluster stats'!$B$21:$B$35,'cluster stats'!$A$21:$A$35) -> 48 | C87: =VLOOKUP(A87,'cluster stats'!$A$2:$B$16,2,FALSE) -> medium reef omnivores | D87: Sheepshead | E87: Archosargus probatocephalus | F87: Teleostei | G87: Sparidae | H87: Archosargus | I87: probatocephalus | J87: 0.75966799 | K87: 11.850442 | L87: 45.466667 | M87: 3.53 | N87: 36.43 | O87: 1.44066 | P87: 0 | Q87: 0.025000001 | R87: 0 | S87: 0.6425 | T87: 0 | U87: 0 | V87: 0.3052 | W87: 0.0273 | X87: nearshore | Y87: reef-associated | Z87: Teleostei | AA87: 0 | AB87: 1 | AC87: 1 | AD87: 1
A88: 5 | B88: =LOOKUP(A88,'cluster stats'!$B$21:$B$35,'cluster stats'!$A$21:$A$35) -> 48 | C88: =VLOOKUP(A88,'cluster stats'!$A$2:$B$16,2,FALSE) -> medium reef omnivores | D88: Hardhead sea catfish | E88: Ariopsis felis | F88: Teleostei | G88: Ariidae | H88: Ariopsis | I88: felis | J88: 0.54140693 | K88: 5.9269301 | L88: 72.403737 | M88: 3.67 | N88: 56.46 | O88: 1.87561 | P88: 0.15761059 | Q88: 0.37335666 | R88: 0.18845289 | S88: 0.0088977754 | T88: 0 | U88: 0 | V88: 0.24708823 | W88: 0.024593852 | X88: nearshore | Y88: reef-associated | Z88: Teleostei | AA88: 1 | AB88: 0 | AC88: 1 | AD88: 0
A89: 5 | B89: =LOOKUP(A89,'cluster stats'!$B$21:$B$35,'cluster stats'!$A$21:$A$35) -> 48 | C89: =VLOOKUP(A89,'cluster stats'!$A$2:$B$16,2,FALSE) -> medium reef omnivores | D89: Atlantic spadefish | E89: Chaetodipterus faber | F89: Teleostei | G89: Ephippidae | H89: Chaetodipterus | I89: faber | J89: 0.63597826 | K89: 6.7699003 | L89: 93.733025 | M89: 4.3533333 | N89: 36.89 | O89: 3.23259 | P89: 0 | Q89: 0.0096617389 | R89: 0.26356744 | S89: 0.038907002 | T89: 0 | U89: 0.36338542 | V89: 0.21513872 | W89: 0.10933968 | X89: nearshore | Y89: reef-associated | Z89: Teleostei | AA89: 0 | AB89: 0 | AC89: 0 | AD89: 0
A90: 5 | B90: =LOOKUP(A90,'cluster stats'!$B$21:$B$35,'cluster stats'!$A$21:$A$35) -> 48 | C90: =VLOOKUP(A90,'cluster stats'!$A$2:$B$16,2,FALSE) -> medium reef omnivores | D90: Jenny mojarra | E90: Eucinostomus gula | F90: Teleostei | G90: Gerreidae | H90: Eucinostomus | I90: gula | J90: 1.0270554 | K90: 11.780579 | L90: 26.802555 | M90: 2.9933333 | N90: 31.78 | O90: 2.13154 | P90: 0.0091539248 | Q90: 0.37272172 | R90: 0.11914373 | S90: 0.12444444 | T90: 0 | U90: 0.0002038736 | V90: 0.35414883 | W90: 0.020183486 | X90: nearshore | Y90: reef-associated | Z90: Teleostei | AA90: 0 | AB90: 0 | AC90: 1 | AD90: 1
A91: 5 | B91: =LOOKUP(A91,'cluster stats'!$B$21:$B$35,'cluster stats'!$A$21:$A$35) -> 48 | C91: =VLOOKUP(A91,'cluster stats'!$A$2:$B$16,2,FALSE) -> medium reef omnivores | D91: White mullet | E91: Mugil curema | F91: Teleostei | G91: Mugilidae | H91: Mugil | I91: curema | J91: 0.2499745 | K91: 24.725527 | L91: 45.5 | M91: 2.215 | N91: 59.24 | O91: 1.90961 | P91: 0 | Q91: 0.0025 | R91: 0.275 | S91: 0.5 | T91: 0 | U91: 0 | V91: 0 | W91: 0.2225 | X91: nearshore | Y91: reef-associated | Z91: Teleostei | AA91: 1 | AB91: 0 | AC91: 0 | AD91: 1
A92: 5 | B92: =LOOKUP(A92,'cluster stats'!$B$21:$B$35,'cluster stats'!$A$21:$A$35) -> 48 | C92: =VLOOKUP(A92,'cluster stats'!$A$2:$B$16,2,FALSE) -> medium reef omnivores | D92: Southern puffer | E92: Sphoeroides nephelus | F92: Teleostei | G92: Tetraodontidae | H92: Sphoeroides | I92: nephelus | J92: 0.92649176 | K92: 16.150953 | L92: 31.451041 | M92: 2.965 | N92: 24.86 | O92: 1.697195 | P92: 0.0090546601 | Q92: 0.15459378 | R92: 0.5866423 | S92: 0.11483082 | T92: 0 | U92: 0 | V92: 0.13487844 | W92: 0 | X92: nearshore | Y92: reef-associated | Z92: Teleostei | AA92: 0 | AB92: 0 | AC92: 0 | AD92: 0
A93: 5 | B93: =LOOKUP(A93,'cluster stats'!$B$21:$B$35,'cluster stats'!$A$21:$A$35) -> 48 | C93: =VLOOKUP(A93,'cluster stats'!$A$2:$B$16,2,FALSE) -> medium reef omnivores | D93: Bandtail puffer | E93: Sphoeroides spengleri | F93: Teleostei | G93: Tetraodontidae | H93: Sphoeroides | I93: spengleri | J93: 0.92649176 | K93: 8.8722956 | L93: 31.451041 | M93: 3.3166667 | N93: 24.86 | O93: 1.97225 | P93: 0.0074 | Q93: 0.3635 | R93: 0 | S93: 0.092799996 | T93: 0 | U93: 0 | V93: 0.5363 | W93: 0 | X93: nearshore | Y93: reef-associated | Z93: Teleostei | AA93: 0 | AB93: 0 | AC93: 1 | AD93: 0
